Workbook

Sheet Hồ sơ
A1: ID | B1: Họ và tên | C1: Giới tính | D1: Ngày sinh | E1: Tuổi | F1: Nghề nghiệp | G1: Trường / Nơi làm việc | H1: SĐT (giả lập) | I1: Email (giả lập) | J1: Địa chỉ hiện tại | K1: Phường | L1: Quận | M1: Mức xác thực (V1–V4) | N1: Xác thực email tổ chức | O1: H1 Cho phép ở ghép khác giới | P1: H2 Khung tuổi ± (năm) | Q1: H3 Ngân sách (triệu/tháng) | R1: H3 Trần ngân sách chấp nhận (triệu/tháng) | S1: H4 Khu vực muốn tìm (quận) | T1: H5 Ngày có thể chuyển vào | U1: H6 Cam kết của mình (tháng) | V1: H6 Yêu cầu cam kết tối thiểu của đối phương (tháng) | W1: A1 Giờ ngủ – giờ dậy [CỨNG] | X1: A2 Làm ca đêm / giờ bất thường [CỨNG] | Y1: A3 Làm việc tại nhà [CỨNG] | Z1: B1 Tiêu chuẩn vệ sinh [CỨNG] | AA1: B2 Tần suất dọn không gian chung [MỀM] | AB1: C1 Mức riêng tư mong muốn [CỨNG] | AC1: C2 Giao tiếp & xử lý mâu thuẫn [MỀM] | AD1: C3 Mức độ thân thiết [MỀM] | AE1: D1 Thuốc lá / vape [CỨNG] | AF1: D2 Dị ứng / sợ động vật [CỨNG] | AG1: D3 Thú cưng [CỨNG] | AH1: D4 Tiếng ồn [MỀM] | AI1: D5 Nhiệt độ, ánh sáng, mùi khi ngủ [MỀM] | AJ1: E1 Nấu ăn & ăn chung [MỀM] | AK1: F1 Khách đến chơi & qua đêm [CỨNG] | AL1: F2 Cách chia chi phí chung [MỀM] | AM1: S1 Đúng hẹn tiền (%) | AN1: Số kỳ thanh toán | AO1: S2 Phản hồi trong 24h (%) | AP1: S3 Show-up Score (1–5) | AQ1: S4 Số review hợp lệ | AR1: S4 Điểm review TB (1–5) | AS1: Báo cáo đã xác minh (90 ngày) | AT1: Nhóm mẫu | AU1: Mã cặp test | AV1: Ghi chú kịch bản
A2: RM001 | B2: Nguyễn Hoài Vy | C2: Nữ | D2: 39629 | E2: =DATEDIF(D2,'Chú giải'!$B$3,"Y") -> 18 | F2: Sinh viên năm 1 | G2: ĐH Ngoại thương | H2: 0900 000 001 | I2: nguyen.hoai.vy.001@example.com | J2: Số 27 ngõ 253 Trịnh Văn Bô, P. Xuân Phương, Q. Nam Từ Liêm, Hà Nội | K2: Xuân Phương | L2: Nam Từ Liêm | M2: V3 | N2: Có | O2: Không | P2: 6 | Q2: 3 | R2: 3.5 | S2: Nam Từ Liêm, Thanh Xuân | T2: 46357 | U2: 6 | V2: 3 | W2: 3 | X2: 1 | Y2: 4 | Z2: 3 | AA2: 4 | AB2: 2 | AC2: 2 | AD2: 2 | AE2: 1 | AF2: 1 | AG2: 1 | AH2: 3 | AI2: 2 | AJ2: 3 | AK2: 2 | AL2: 2 | AM2: 88 | AN2: 12 | AO2: 94 | AP2: 4.6 | AQ2: 0 | AS2: 0 | AT2: Ngẫu nhiên
A3: RM002 | B3: Đỗ Bảo Anh | C3: Nữ | D3: 37001 | E3: =DATEDIF(D3,'Chú giải'!$B$3,"Y") -> 25 | F3: Nhân viên văn phòng | G3: Công ty CP Phần mềm Hà Thành | H3: 0900 000 002 | I3: do.bao.anh.002@example.com | J3: Số 3 ngõ 55 Nguyễn Văn Lộc, P. Mộ Lao, Q. Hà Đông, Hà Nội | K3: Mộ Lao | L3: Hà Đông | M3: V2 | N3: Không | O3: Không | P3: 6 | Q3: 3 | R3: 3.5 | T3: 46327 | U3: 6 | V3: 3 | W3: 2 | X3: 1 | Y3: 2 | Z3: 2 | AA3: 2 | AB3: 2 | AC3: 1 | AD3: 2 | AE3: 1 | AF3: 1 | AG3: 1 | AH3: 2 | AI3: 2 | AJ3: 2 | AK3: 2 | AL3: 1 | AN3: 0 | AQ3: 0 | AS3: 0 | AT3: Test đặc biệt | AU3: P13 | AV3: P13 · Bên B: Nhóm A cực đoan – ca đêm
A4: RM003 | B4: Nguyễn Minh Cường | C4: Nam | D4: 38155 | E4: =DATEDIF(D4,'Chú giải'!$B$3,"Y") -> 22 | F4: Sinh viên năm 4 | G4: ĐH Ngoại thương | H4: 0900 000 003 | I4: nguyen.minh.cuong.003@example.com | J4: Số 4 ngõ 214 Mễ Trì Hạ, P. Mễ Trì, Q. Nam Từ Liêm, Hà Nội | K4: Mễ Trì | L4: Nam Từ Liêm | M4: V4 | N4: Có | O4: Không | P4: 6 | Q4: 1.5 | R4: 2 | S4: Long Biên, Nam Từ Liêm | T4: 46366 | U4: 9 | V4: 3 | W4: 3 | X4: 1 | Y4: 2 | Z4: 1 | AA4: 2 | AE4: 1 | AF4: 1 | AG4: 1 | AH4: 4 | AI4: 2 | AJ4: 1 | AK4: 1 | AL4: 1 | AM4: 69 | AN4: 3 | AO4: 41 | AP4: 3.6 | AQ4: 0 | AS4: 0 | AT4: Ngẫu nhiên – thiếu dữ liệu | AV4: Bỏ trống: C1, C2, C3
A5: RM004 | B5: Vũ Quốc Tiến | C5: Nam | D5: 36984 | E5: =DATEDIF(D5,'Chú giải'!$B$3,"Y") -> 25 | F5: Nhân viên văn phòng | G5: Công ty CP Phần mềm Hà Thành | H5: 0900 000 004 | I5: vu.quoc.tien.004@example.com | J5: Số 250 Xuân Thủy, P. Dịch Vọng Hậu, Q. Cầu Giấy, Hà Nội | K5: Dịch Vọng Hậu | L5: Cầu Giấy | M5: V2 | N5: Không | O5: Không | P5: 6 | Q5: 3 | R5: 3.5 | T5: 46327 | U5: 6 | V5: 3 | W5: 2 | X5: 1 | Y5: 2 | Z5: 2 | AA5: 2 | AB5: 2 | AC5: 1 | AD5: 2 | AE5: 1 | AF5: 1 | AG5: 1 | AH5: 2 | AI5: 2 | AJ5: 2 | AK5: 2 | AL5: 1 | AN5: 0 | AQ5: 0 | AS5: 0 | AT5: Test đặc biệt | AU5: P19 | AV5: P19 · Bên B: Phạt D4≥3 × A1∈{1,2}
A6: RM005 | B6: Phạm Hồng Hằng | C6: Nữ | D6: 37693 | E6: =DATEDIF(D6,'Chú giải'!$B$3,"Y") -> 23 | F6: Nhân viên văn phòng | G6: Công ty TNHH Tư vấn Bắc Hà | H6: 0900 000 005 | I6: pham.hong.hang.005@example.com | J6: Số 310 Bằng Liệt, P. Hoàng Liệt, Q. Hoàng Mai, Hà Nội | K6: Hoàng Liệt | L6: Hoàng Mai | M6: V2 | N6: Không | O6: Không | P6: 6 | Q6: 3 | R6: 3.5 | T6: 46327 | U6: 6 | V6: 3 | W6: 2 | X6: 1 | Y6: 2 | Z6: 2 | AA6: 1 | AB6: 2 | AC6: 1 | AD6: 2 | AE6: 1 | AF6: 1 | AG6: 1 | AH6: 2 | AI6: 2 | AJ6: 4 | AK6: 2 | AL6: 1 | AN6: 0 | AQ6: 0 | AS6: 0 | AT6: Test đặc biệt | AU6: P22 | AV6: P22 · Bên A: Cộng dồn ba phạt nhỏ
A7: RM006 | B7: Nguyễn Thanh Hằng | C7: Nữ | D7: 37057 | E7: =DATEDIF(D7,'Chú giải'!$B$3,"Y") -> 25 | F7: Nhân viên văn phòng | G7: Công ty CP Phần mềm Hà Thành | H7: 0900 000 006 | I7: nguyen.thanh.hang.006@example.com | J7: Số 15 ngõ 207 Giảng Võ, P. Giảng Võ, Q. Ba Đình, Hà Nội | K7: Giảng Võ | L7: Ba Đình | M7: V2 | N7: Không | O7: Không | P7: 6 | Q7: 3 | R7: 3.5 | T7: 46327 | U7: 6 | V7: 3 | W7: 2 | X7: 1 | Y7: 2 | Z7: 2 | AA7: 2 | AB7: 1 | AC7: 1 | AD7: 2 | AE7: 1 | AF7: 1 | AG7: 1 | AH7: 2 | AI7: 2 | AJ7: 2 | AK7: 3 | AL7: 1 | AN7: 0 | AQ7: 0 | AS7: 0 | AT7: Test đặc biệt | AU7: P18 | AV7: P18 · Bên B: Phạt F1=4 × C1=1
A8: RM007 | B8: Trần Mai Ánh | C8: Nữ | D8: 37718 | E8: =DATEDIF(D8,'Chú giải'!$B$3,"Y") -> 23 | F8: Sinh viên năm 4 | G8: ĐH Công nghệ – ĐHQGHN | H8: 0900 000 007 | I8: tran.mai.anh.007@example.com | J8: Số 25 ngõ 115 Phúc La, P. Phúc La, Q. Hà Đông, Hà Nội | K8: Phúc La | L8: Hà Đông | M8: V4 | N8: Không | O8: Không | P8: 4 | Q8: 2.5 | R8: 4 | T8: 46339 | U8: 9 | V8: 3 | W8: 3 | X8: 1 | Y8: 2 | Z8: 3 | AA8: 1 | AB8: 1 | AC8: 1 | AD8: 2 | AE8: 1 | AF8: 1 | AG8: 3 | AH8: 4 | AI8: 2 | AJ8: 2 | AK8: 1 | AL8: 2 | AN8: 0 | AQ8: 0 | AS8: 0 | AT8: Ngẫu nhiên
A9: RM008 | B9: Lê Thành Thịnh | C9: Nam | D9: 37045 | E9: =DATEDIF(D9,'Chú giải'!$B$3,"Y") -> 25 | F9: Nhân viên văn phòng | G9: Công ty CP Phần mềm Hà Thành | H9: 0900 000 008 | I9: le.thanh.thinh.008@example.com | J9: Số 2 ngõ 222 Trương Định, P. Bạch Mai, Q. Hai Bà Trưng, Hà Nội | K9: Bạch Mai | L9: Hai Bà Trưng | M9: V2 | N9: Không | O9: Không | P9: 6 | Q9: 3 | R9: 3.5 | T9: 46348 | U9: 6 | V9: 3 | W9: 2 | X9: 1 | Y9: 2 | Z9: 2 | AA9: 2 | AB9: 2 | AC9: 1 | AD9: 2 | AE9: 1 | AF9: 1 | AG9: 1 | AH9: 2 | AI9: 2 | AJ9: 2 | AK9: 2 | AL9: 1 | AN9: 0 | AQ9: 0 | AS9: 0 | AT9: Test đặc biệt | AU9: P11 | AV9: P11 · Bên B: Ngày chuyển vào chênh đúng 21 ngày
A10: RM009 | B10: Nguyễn Hồng Yến | C10: Nữ | D10: 36930 | E10: =DATEDIF(D10,'Chú giải'!$B$3,"Y") -> 25 | F10: Nhân viên văn phòng | G10: Công ty CP Phần mềm Hà Thành | H10: 0900 000 009 | I10: nguyen.hong.yen.009@example.com | J10: Số 225 Thái Thịnh, P. Thịnh Quang, Q. Đống Đa, Hà Nội | K10: Thịnh Quang | L10: Đống Đa | M10: V3 | N10: Không | O10: Có | P10: 6 | Q10: 3 | R10: 3.5 | T10: 46327 | U10: 6 | V10: 3 | W10: 2 | X10: 1 | Y10: 2 | Z10: 2 | AA10: 2 | AB10: 2 | AC10: 1 | AD10: 2 | AE10: 1 | AF10: 1 | AG10: 1 | AH10: 2 | AI10: 2 | AJ10: 2 | AK10: 2 | AL10: 1 | AN10: 0 | AQ10: 0 | AS10: 0 | AT10: Test đặc biệt | AU10: P05 | AV10: P05 · Bên B: Khác giới hợp lệ
A11: RM010 | B11: Dương Gia Huy | C11: Nam | D11: 36324 | E11: =DATEDIF(D11,'Chú giải'!$B$3,"Y") -> 27 | F11: Điều dưỡng (làm ca kíp) | G11: Bệnh viện đa khoa tư nhân An Phúc | H11: 0900 000 010 | I11: duong.gia.huy.010@example.com | J11: Số 220 Nguyễn Tuân, P. Thanh Xuân Trung, Q. Thanh Xuân, Hà Nội | K11: Thanh Xuân Trung | L11: Thanh Xuân | M11: V2 | N11: Có | O11: Không | P11: 6 | Q11: 4 | R11: 4 | S11: Nam Từ Liêm, Thanh Xuân | T11: 46363 | U11: 6 | V11: 3 | W11: 2 | X11: 3 | Y11: 1 | Z11: 2 | AA11: 1 | AB11: 3 | AC11: 2 | AD11: 2 | AE11: 2 | AF11: 1 | AG11: 1 | AH11: 2 | AI11: 2 | AJ11: 2 | AK11: 2 | AL11: 1 | AM11: 86 | AN11: 7 | AO11: 48 | AP11: 3 | AQ11: 0 | AS11: 0 | AT11: Ngẫu nhiên
A12: RM011 | B12: Đỗ Khánh Hương | C12: Nữ | D12: 37775 | E12: =DATEDIF(D12,'Chú giải'!$B$3,"Y") -> 23 | F12: Nhân viên văn phòng | G12: Công ty CP Phần mềm Hà Thành | H12: 0900 000 011 | I12: do.khanh.huong.011@example.com | J12: Số 59 Xuân Thủy, P. Dịch Vọng Hậu, Q. Cầu Giấy, Hà Nội | K12: Dịch Vọng Hậu | L12: Cầu Giấy | M12: V4 | N12: Có | O12: Không | P12: 6 | Q12: 3 | R12: 3.5 | T12: 46327 | U12: 6 | V12: 3 | W12: 2 | X12: 1 | Y12: 2 | Z12: 2 | AA12: 2 | AB12: 2 | AC12: 1 | AD12: 2 | AE12: 1 | AF12: 1 | AG12: 1 | AH12: 2 | AI12: 2 | AJ12: 2 | AK12: 2 | AL12: 1 | AM12: 95 | AN12: 6 | AO12: 90 | AP12: 4.5 | AQ12: 3 | AR12: 4.8 | AS12: 0 | AT12: Test đặc biệt | AU12: P01 | AV12: P01 · Bên A: Cặp lý tưởng, bonus vượt trần
A13: RM012 | B13: Phạm Công Huy | C13: Nam | D13: 36557 | E13: =DATEDIF(D13,'Chú giải'!$B$3,"Y") -> 26 | F13: Giáo viên | G13: Trung tâm Anh ngữ Sunrise Hà Nội | H13: 0900 000 012 | I13: pham.cong.huy.012@example.com | J13: Số 3 ngõ 67 Hào Nam, P. Ô Chợ Dừa, Q. Đống Đa, Hà Nội | K13: Ô Chợ Dừa | L13: Đống Đa | M13: V2 | N13: Có | O13: Có | P13: 5 | Q13: 3 | R13: 4 | T13: 46364 | U13: 6 | V13: 6 | W13: 1 | X13: 1 | Y13: 1 | Z13: 1 | AA13: 3 | AB13: 2 | AC13: 1 | AD13: 2 | AE13: 2 | AF13: 1 | AG13: 1 | AH13: 2 | AI13: 1 | AJ13: 1 | AK13: 4 | AL13: 1 | AM13: 96 | AN13: 11 | AO13: 83 | AP13: 4.8 | AQ13: 4 | AR13: 4.6 | AS13: 0 | AT13: Ngẫu nhiên
A14: RM013 | B14: Đỗ Minh Bách | C14: Nam | D14: 37769 | E14: =DATEDIF(D14,'Chú giải'!$B$3,"Y") -> 23 | F14: Nhân viên văn phòng | G14: Công ty TNHH Tư vấn Bắc Hà | H14: 0900 000 013 | I14: do.minh.bach.013@example.com | J14: Số 4 ngõ 11 Bằng Liệt, P. Hoàng Liệt, Q. Hoàng Mai, Hà Nội | K14: Hoàng Liệt | L14: Hoàng Mai | M14: V2 | N14: Không | O14: Không | P14: 6 | Q14: 3 | R14: 3.5 | T14: 46327 | U14: 6 | V14: 3 | W14: 2 | X14: 1 | Y14: 2 | Z14: 2 | AA14: 2 | AB14: 2 | AC14: 1 | AD14: 2 | AE14: 1 | AF14: 1 | AG14: 1 | AH14: 2 | AI14: 2 | AJ14: 2 | AK14: 2 | AL14: 1 | AN14: 0 | AQ14: 0 | AS14: 0 | AT14: Test đặc biệt | AU14: P11 | AV14: P11 · Bên A: Ngày chuyển vào chênh đúng 21 ngày
A15: RM014 | B15: Nguyễn Việt Tiến | C15: Nam | D15: 37666 | E15: =DATEDIF(D15,'Chú giải'!$B$3,"Y") -> 23 | F15: Nhân viên văn phòng | G15: Công ty TNHH Tư vấn Bắc Hà | H15: 0900 000 014 | I15: nguyen.viet.tien.014@example.com | J15: Số 11 ngõ 50 Mễ Trì Hạ, P. Mễ Trì, Q. Nam Từ Liêm, Hà Nội | K15: Mễ Trì | L15: Nam Từ Liêm | M15: V2 | N15: Không | O15: Không | P15: 6 | Q15: 3 | R15: 3.5 | T15: 46327 | U15: 6 | V15: 3 | W15: 2 | X15: 1 | Y15: 2 | Z15: 2 | AA15: 2 | AB15: 2 | AC15: 1 | AD15: 2 | AE15: 1 | AF15: 2 | AG15: 1 | AH15: 2 | AI15: 2 | AJ15: 2 | AK15: 2 | AL15: 1 | AN15: 0 | AQ15: 0 | AS15: 0 | AT15: Test đặc biệt | AU15: P16 | AV15: P16 · Bên A: Dị ứng nhẹ × thú lớn
A16: RM015 | B16: Đặng Quang Vinh | C16: Nam | D16: 38390 | E16: =DATEDIF(D16,'Chú giải'!$B$3,"Y") -> 21 | F16: Sinh viên năm 3 | G16: ĐH Luật Hà Nội | H16: 0900 000 015 | I16: dang.quang.vinh.015@example.com | J16: Số 38 Lê Đức Thọ, P. Mỹ Đình 1, Q. Nam Từ Liêm, Hà Nội | K16: Mỹ Đình 1 | L16: Nam Từ Liêm | M16: V3 | N16: Có | O16: Không | P16: 6 | Q16: 3.5 | R16: 4.5 | S16: Hai Bà Trưng, Nam Từ Liêm | T16: 46333 | U16: 6 | V16: 3 | W16: 2 | X16: 1 | Y16: 2 | Z16: 3 | AA16: 1 | AB16: 2 | AC16: 2 | AD16: 2 | AE16: 1 | AF16: 1 | AG16: 1 | AH16: 1 | AI16: 1 | AJ16: 2 | AK16: 2 | AL16: 3 | AM16: 100 | AN16: 4 | AO16: 92 | AP16: 4.5 | AQ16: 3 | AR16: 4.9 | AS16: 0 | AT16: Ngẫu nhiên
A17: RM016 | B17: Mai Minh Quân | C17: Nam | D17: 37701 | E17: =DATEDIF(D17,'Chú giải'!$B$3,"Y") -> 23 | F17: Nhân viên văn phòng | G17: Công ty TNHH Tư vấn Bắc Hà | H17: 0900 000 016 | I17: mai.minh.quan.016@example.com | J17: Số 77 Kim Đồng, P. Định Công, Q. Hoàng Mai, Hà Nội | K17: Định Công | L17: Hoàng Mai | M17: V2 | N17: Không | O17: Không | P17: 6 | Q17: 3 | R17: 3.5 | T17: 46327 | U17: 6 | V17: 3 | W17: 3 | X17: 1 | Y17: 2 | Z17: 2 | AA17: 2 | AB17: 2 | AC17: 1 | AD17: 2 | AE17: 1 | AF17: 1 | AG17: 1 | AH17: 3 | AI17: 2 | AJ17: 2 | AK17: 4 | AL17: 1 | AN17: 0 | AQ17: 0 | AS17: 0 | AT17: Test đặc biệt | AU17: P24 | AV17: P24 · Bên A: Phạt chạm sàn −0,35
A18: RM017 | B18: Hồ Thanh Ánh | C18: Nữ | D18: 36272 | E18: =DATEDIF(D18,'Chú giải'!$B$3,"Y") -> 27 | F18: Kế toán | G18: Công ty CP Xây dựng & Đầu tư Hồng Hà | H18: 0900 000 017 | I18: ho.thanh.anh.017@example.com | J18: Số 15 ngõ 100 Kim Mã, P. Kim Mã, Q. Ba Đình, Hà Nội | K18: Kim Mã | L18: Ba Đình | M18: V2 | N18: Có | O18: Không | P18: 6 | Q18: 3.5 | R18: 5 | S18: Ba Đình, Hoàng Mai | T18: 46365 | U18: 12 | V18: 6 | W18: 2 | X18: 1 | Y18: 2 | Z18: 2 | AA18: 3 | AB18: 3 | AC18: 1 | AD18: 3 | AE18: 1 | AF18: 1 | AG18: 3 | AH18: 1 | AI18: 1 | AJ18: 1 | AK18: 1 | AL18: 1 | AN18: 0 | AQ18: 0 | AS18: 0 | AT18: Ngẫu nhiên
A19: RM018 | B19: Nguyễn Thị Vy | C19: Nữ | D19: 37644 | E19: =DATEDIF(D19,'Chú giải'!$B$3,"Y") -> 23 | F19: Kỹ sư xây dựng | G19: Công ty CP Xây dựng & Đầu tư Hồng Hà | H19: 0900 000 018 | I19: nguyen.thi.vy.018@example.com | J19: Số 18 ngõ 180 Nguyễn Xiển, P. Hạ Đình, Q. Thanh Xuân, Hà Nội | K19: Hạ Đình | L19: Thanh Xuân | M19: V1 | N19: Không | O19: Không | P19: 6 | Q19: 4.5 | R19: 5 | S19: Thanh Xuân, Tây Hồ | T19: 46341 | U19: 6 | V19: 3 | W19: 3 | X19: 1 | Y19: 1 | Z19: 2 | AA19: 2 | AB19: 2 | AC19: 1 | AD19: 1 | AE19: 1 | AF19: 1 | AG19: 1 | AH19: 3 | AI19: 1 | AJ19: 2 | AK19: 2 | AL19: 1 | AM19: 92 | AN19: 6 | AO19: 58 | AP19: 3.1 | AQ19: 0 | AS19: 0 | AT19: Ngẫu nhiên
A20: RM019 | B20: Lê Thành Đạt | C20: Nam | D20: 37746 | E20: =DATEDIF(D20,'Chú giải'!$B$3,"Y") -> 23 | F20: Nhân viên văn phòng | G20: Công ty TNHH Tư vấn Bắc Hà | H20: 0900 000 019 | I20: le.thanh.dat.019@example.com | J20: Số 5 ngõ 245 Hoàng Minh Giám, P. Yên Hòa, Q. Cầu Giấy, Hà Nội | K20: Yên Hòa | L20: Cầu Giấy | M20: V2 | N20: Không | O20: Không | P20: 6 | Q20: 3 | R20: 3.5 | T20: 46327 | U20: 6 | V20: 3 | W20: 2 | X20: 1 | Y20: 2 | Z20: 2 | AA20: 2 | AB20: 2 | AC20: 1 | AD20: 2 | AE20: 1 | AF20: 2 | AG20: 1 | AH20: 2 | AI20: 2 | AJ20: 2 | AK20: 2 | AL20: 1 | AN20: 0 | AQ20: 0 | AS20: 0 | AT20: Test đặc biệt | AU20: P17 | AV20: P17 · Bên A: Dị ứng nhẹ × thú nhỏ
A21: RM020 | B21: Đặng Hồng Uyên | C21: Nữ | D21: 38532 | E21: =DATEDIF(D21,'Chú giải'!$B$3,"Y") -> 21 | F21: Sinh viên năm 3 | G21: ĐH Khoa học Xã hội và Nhân văn – ĐHQGHN | H21: 0900 000 020 | I21: dang.hong.uyen.020@example.com | J21: Số 6 ngõ 20 Minh Khai, P. Đồng Tâm, Q. Hai Bà Trưng, Hà Nội | K21: Đồng Tâm | L21: Hai Bà Trưng | M21: V4 | N21: Không | O21: Không | P21: 6 | Q21: 2.5 | R21: 4 | T21: 46341 | U21: 12 | V21: 6 | W21: 2 | X21: 1 | Y21: 2 | Z21: 4 | AA21: 3 | AB21: 2 | AC21: 2 | AD21: 3 | AE21: 1 | AF21: 1 | AG21: 3 | AH21: 2 | AI21: 1 | AJ21: 1 | AK21: 2 | AL21: 2 | AM21: 96 | AN21: 11 | AO21: 55 | AP21: 3.5 | AQ21: 1 | AR21: 4.8 | AS21: 0 | AT21: Ngẫu nhiên
A22: RM021 | B22: Nguyễn Công Dũng | C22: Nam | D22: 38871 | E22: =DATEDIF(D22,'Chú giải'!$B$3,"Y") -> 20 | F22: Sinh viên năm 2 | G22: ĐH Kinh tế Quốc dân | H22: 0900 000 021 | I22: nguyen.cong.dung.021@example.com | J22: Số 4 ngõ 238 Nguyễn Ngọc Nại, P. Khương Trung, Q. Thanh Xuân, Hà Nội | K22: Khương Trung | L22: Thanh Xuân | M22: V2 | N22: Không | O22: Không | P22: 6 | Q22: 3 | R22: 3.5 | T22: 46327 | U22: 6 | V22: 3 | W22: 2 | X22: 1 | Y22: 2 | Z22: 2 | AA22: 2 | AB22: 2 | AC22: 1 | AD22: 2 | AE22: 1 | AF22: 1 | AG22: 1 | AH22: 2 | AI22: 2 | AJ22: 2 | AK22: 2 | AL22: 1 | AN22: 0 | AQ22: 0 | AS22: 0 | AT22: Test đặc biệt | AU22: P06 | AV22: P06 · Bên A: Lệch tuổi vượt khung
A23: RM022 | B23: Đinh Gia Bảo | C23: Nam | D23: 37038 | E23: =DATEDIF(D23,'Chú giải'!$B$3,"Y") -> 25 | F23: Nhân viên văn phòng | G23: Công ty CP Phần mềm Hà Thành | H23: 0900 000 022 | I23: dinh.gia.bao.022@example.com | J23: Số 3 ngõ 53 Định Công, P. Định Công, Q. Hoàng Mai, Hà Nội | K23: Định Công | L23: Hoàng Mai | M23: V2 | N23: Không | O23: Không | P23: 6 | Q23: 3 | R23: 3.5 | T23: 46327 | U23: 6 | V23: 3 | W23: 2 | X23: 1 | Y23: 2 | Z23: 2 | AA23: 2 | AB23: 2 | AC23: 1 | AD23: 2 | AE23: 3 | AF23: 1 | AG23: 1 | AH23: 2 | AI23: 2 | AJ23: 2 | AK23: 2 | AL23: 1 | AN23: 0 | AQ23: 0 | AS23: 0 | AT23: Test đặc biệt | AU23: P26 | AV23: P26 · Bên B: Hút thuốc trong phòng × không hút
A24: RM023 | B24: Lương Việt Lâm | C24: Nam | D24: 35191 | E24: =DATEDIF(D24,'Chú giải'!$B$3,"Y") -> 30 | F24: Thiết kế đồ họa (freelance) | G24: Freelance | H24: 0900 000 023 | I24: luong.viet.lam.023@example.com | J24: Số 27 ngõ 93 Nguyễn Chí Thanh, P. Liễu Giai, Q. Ba Đình, Hà Nội | K24: Liễu Giai | L24: Ba Đình | M24: V2 | N24: Không | O24: Không | P24: 6 | Q24: 4.5 | R24: 6 | S24: Ba Đình, Nam Từ Liêm | T24: 46364 | U24: 9 | V24: 3 | W24: 3 | X24: 1 | Y24: 4 | Z24: 2 | AB24: 3 | AC24: 1 | AF24: 1 | AG24: 1 | AH24: 4 | AI24: 1 | AJ24: 2 | AL24: 1 | AN24: 0 | AQ24: 0 | AS24: 0 | AT24: Ngẫu nhiên – thiếu dữ liệu | AV24: Bỏ trống: B2, C3, D1, F1
A25: RM024 | B25: Hoàng Ngọc Trang | C25: Nữ | D25: 38157 | E25: =DATEDIF(D25,'Chú giải'!$B$3,"Y") -> 22 | F25: Sinh viên năm 4 | G25: Học viện Báo chí và Tuyên truyền | H25: 0900 000 024 | I25: hoang.ngoc.trang.024@example.com | J25: Số 5 ngõ 154 Việt Hưng, P. Việt Hưng, Q. Long Biên, Hà Nội | K25: Việt Hưng | L25: Long Biên | M25: V1 | N25: Không | O25: Không | P25: 6 | Q25: 3 | R25: 3 | S25: Hai Bà Trưng, Long Biên | T25: 46313 | U25: 6 | V25: 6 | W25: 2 | X25: 1 | Y25: 2 | Z25: 3 | AA25: 3 | AB25: 2 | AC25: 3 | AD25: 3 | AE25: 1 | AF25: 1 | AG25: 1 | AH25: 2 | AI25: 2 | AJ25: 2 | AK25: 4 | AL25: 4 | AN25: 0 | AQ25: 0 | AS25: 0 | AT25: Ngẫu nhiên
A26: RM025 | B26: Vũ Gia Tùng | C26: Nam | D26: 38459 | E26: =DATEDIF(D26,'Chú giải'!$B$3,"Y") -> 21 | F26: Sinh viên năm 3 | G26: ĐH Xây dựng Hà Nội | H26: 0900 000 025 | I26: vu.gia.tung.025@example.com | J26: Số 98 Đức Thắng, P. Đức Thắng, Q. Bắc Từ Liêm, Hà Nội | K26: Đức Thắng | L26: Bắc Từ Liêm | M26: V2 | N26: Không | O26: Không | P26: 6 | Q26: 2.5 | R26: 3 | T26: 46344 | U26: 12 | V26: 3 | W26: 3 | X26: 1 | Y26: 4 | Z26: 2 | AA26: 3 | AB26: 2 | AC26: 1 | AD26: 1 | AE26: 1 | AF26: 2 | AG26: 1 | AH26: 1 | AI26: 2 | AJ26: 3 | AK26: 4 | AL26: 4 | AN26: 0 | AQ26: 0 | AS26: 1 | AT26: Ngẫu nhiên
A27: RM026 | B27: Đặng Ngọc Phương | C27: Nữ | D27: 37002 | E27: =DATEDIF(D27,'Chú giải'!$B$3,"Y") -> 25 | F27: Nhân viên văn phòng | G27: Công ty CP Phần mềm Hà Thành | H27: 0900 000 026 | I27: dang.ngoc.phuong.026@example.com | J27: Số 5 ngõ 83 Thanh Nhàn, P. Thanh Nhàn, Q. Hai Bà Trưng, Hà Nội | K27: Thanh Nhàn | L27: Hai Bà Trưng | M27: V2 | N27: Không | O27: Không | P27: 6 | Q27: 3 | R27: 3.5 | T27: 46327 | U27: 6 | V27: 3 | W27: 3 | X27: 1 | Y27: 2 | Z27: 2 | AA27: 2 | AB27: 2 | AC27: 1 | AD27: 2 | AE27: 1 | AF27: 1 | AG27: 1 | AH27: 3 | AI27: 2 | AJ27: 2 | AK27: 2 | AL27: 1 | AN27: 0 | AQ27: 0 | AS27: 0 | AT27: Test đặc biệt | AU27: P20 | AV27: P20 · Bên B: Phạt A3≥3 × D4≥3
A28: RM027 | B28: Kiều Quang Tiến | C28: Nam | D28: 37686 | E28: =DATEDIF(D28,'Chú giải'!$B$3,"Y") -> 23 | F28: Nhân viên văn phòng | G28: Công ty TNHH Tư vấn Bắc Hà | H28: 0900 000 027 | I28: kieu.quang.tien.027@example.com | J28: Số 28 ngõ 203 Hồ Tùng Mậu, P. Cầu Diễn, Q. Nam Từ Liêm, Hà Nội | K28: Cầu Diễn | L28: Nam Từ Liêm | M28: V2 | N28: Không | O28: Không | P28: 6 | Q28: 3 | R28: 3.5 | T28: 46327 | U28: 6 | V28: 3 | X28: 1 | Y28: 2 | AA28: 2 | AB28: 2 | AC28: 1 | AD28: 2 | AE28: 1 | AF28: 1 | AG28: 1 | AI28: 2 | AJ28: 2 | AK28: 2 | AL28: 1 | AN28: 0 | AQ28: 0 | AS28: 0 | AT28: Test đặc biệt | AU28: P25 | AV28: P25 · Bên A: Bỏ trống câu hỏi
A29: RM028 | B29: Cao Kim Yến | C29: Nữ | D29: 37670 | E29: =DATEDIF(D29,'Chú giải'!$B$3,"Y") -> 23 | F29: Chuyên viên Marketing | G29: Agency Truyền thông Sao Bắc | H29: 0900 000 028 | I29: cao.kim.yen.028@example.com | J29: Số 7 ngõ 53 Lê Văn Lương, P. Nhân Chính, Q. Thanh Xuân, Hà Nội | K29: Nhân Chính | L29: Thanh Xuân | M29: V3 | N29: Có | O29: Không | P29: 6 | Q29: 6 | R29: 6.5 | S29: Hai Bà Trưng, Thanh Xuân | T29: 46354 | U29: 6 | V29: 6 | W29: 3 | X29: 2 | Y29: 3 | Z29: 3 | AA29: 2 | AB29: 3 | AC29: 3 | AD29: 3 | AE29: 1 | AF29: 1 | AG29: 1 | AH29: 1 | AI29: 3 | AJ29: 3 | AK29: 1 | AL29: 1 | AN29: 0 | AQ29: 0 | AS29: 0 | AT29: Ngẫu nhiên
A30: RM029 | B30: Cao Xuân Dương | C30: Nam | D30: 37049 | E30: =DATEDIF(D30,'Chú giải'!$B$3,"Y") -> 25 | F30: Nhân viên văn phòng | G30: Công ty CP Phần mềm Hà Thành | H30: 0900 000 029 | I30: cao.xuan.duong.029@example.com | J30: Số 11 ngõ 162 Nguyễn Chí Thanh, P. Liễu Giai, Q. Ba Đình, Hà Nội | K30: Liễu Giai | L30: Ba Đình | M30: V2 | N30: Không | O30: Không | P30: 6 | Q30: 3 | R30: 3.5 | T30: 46327 | U30: 6 | V30: 3 | W30: 2 | X30: 1 | Y30: 3 | Z30: 2 | AA30: 2 | AB30: 1 | AC30: 1 | AD30: 2 | AE30: 1 | AF30: 1 | AG30: 1 | AH30: 2 | AI30: 2 | AJ30: 2 | AK30: 3 | AL30: 1 | AN30: 0 | AQ30: 0 | AS30: 0 | AT30: Test đặc biệt | AU30: P24 | AV30: P24 · Bên B: Phạt chạm sàn −0,35
A31: RM030 | B31: Lương Ngọc Nhung | C31: Nữ | D31: 36993 | E31: =DATEDIF(D31,'Chú giải'!$B$3,"Y") -> 25 | F31: Nhân viên văn phòng | G31: Công ty CP Phần mềm Hà Thành | H31: 0900 000 030 | I31: luong.ngoc.nhung.030@example.com | J31: Số 29 ngõ 136 Vĩnh Tuy, P. Vĩnh Tuy, Q. Hai Bà Trưng, Hà Nội | K31: Vĩnh Tuy | L31: Hai Bà Trưng | M31: V2 | N31: Không | O31: Không | P31: 6 | Q31: 3 | R31: 3.5 | T31: 46349 | U31: 6 | V31: 3 | W31: 2 | X31: 1 | Y31: 2 | Z31: 2 | AA31: 2 | AB31: 2 | AC31: 1 | AD31: 2 | AE31: 1 | AF31: 1 | AG31: 1 | AH31: 2 | AI31: 2 | AJ31: 2 | AK31: 2 | AL31: 1 | AN31: 0 | AQ31: 0 | AS31: 0 | AT31: Test đặc biệt | AU31: P10 | AV31: P10 · Bên B: Ngày chuyển vào chênh 22 ngày
A32: RM031 | B32: Nguyễn Phương Anh | C32: Nữ | D32: 36952 | E32: =DATEDIF(D32,'Chú giải'!$B$3,"Y") -> 25 | F32: Nhân viên văn phòng | G32: Công ty CP Phần mềm Hà Thành | H32: 0900 000 031 | I32: nguyen.phuong.anh.031@example.com | J32: Số 15 ngõ 188 Nguyễn Văn Lộc, P. Mộ Lao, Q. Hà Đông, Hà Nội | K32: Mộ Lao | L32: Hà Đông | M32: V2 | N32: Không | O32: Không | P32: 6 | Q32: 3 | R32: 3.5 | T32: 46327 | U32: 6 | V32: 3 | W32: 2 | X32: 1 | Y32: 2 | Z32: 2 | AA32: 2 | AB32: 2 | AC32: 1 | AD32: 2 | AE32: 1 | AF32: 1 | AG32: 1 | AH32: 2 | AI32: 2 | AJ32: 2 | AK32: 2 | AL32: 1 | AN32: 0 | AQ32: 0 | AS32: 0 | AT32: Test đặc biệt | AU32: P23 | AV32: P23 · Bên B: Có ≥2 báo cáo đã xác minh
A33: RM032 | B33: Nguyễn Thành Tài | C33: Nam | D33: 33988 | E33: =DATEDIF(D33,'Chú giải'!$B$3,"Y") -> 33 | F33: Biên – phiên dịch (freelance) | G33: Freelance | H33: 0900 000 032 | I33: nguyen.thanh.tai.032@example.com | J33: Số 8 ngõ 101 Bạch Mai, P. Bạch Mai, Q. Hai Bà Trưng, Hà Nội | K33: Bạch Mai | L33: Hai Bà Trưng | M33: V1 | N33: Không | O33: Không | P33: 8 | Q33: 3.5 | R33: 5 | S33: Hai Bà Trưng | T33: 46310 | U33: 3 | V33: 3 | W33: 3 | X33: 1 | Y33: 4 | Z33: 3 | AA33: 3 | AB33: 1 | AC33: 3 | AD33: 1 | AE33: 1 | AF33: 1 | AG33: 2 | AH33: 2 | AI33: 1 | AJ33: 4 | AK33: 2 | AL33: 1 | AM33: 59 | AN33: 6 | AO33: 78 | AP33: 3.3 | AQ33: 0 | AS33: 0 | AT33: Ngẫu nhiên
A34: RM033 | B34: Đặng Thu Châu | C34: Nữ | D34: 37282 | E34: =DATEDIF(D34,'Chú giải'!$B$3,"Y") -> 24 | F34: Biên – phiên dịch (freelance) | G34: Freelance | H34: 0900 000 033 | I34: dang.thu.chau.033@example.com | J34: Số 30 ngõ 159 Định Công, P. Định Công, Q. Hoàng Mai, Hà Nội | K34: Định Công | L34: Hoàng Mai | M34: V2 | N34: Không | O34: Có | P34: 6 | Q34: 4 | R34: 4.5 | S34: Hai Bà Trưng, Hoàng Mai | T34: 46319 | U34: 6 | V34: 3 | W34: 1 | X34: 3 | Y34: 3 | Z34: 4 | AA34: 4 | AB34: 2 | AC34: 2 | AD34: 1 | AE34: 1 | AF34: 1 | AG34: 1 | AH34: 2 | AI34: 2 | AJ34: 1 | AK34: 2 | AL34: 1 | AM34: 99 | AN34: 6 | AO34: 98 | AP34: 3.4 | AQ34: 2 | AR34: 3.6 | AS34: 0 | AT34: Ngẫu nhiên
A35: RM034 | B35: Nguyễn Thanh Giang | C35: Nữ | D35: 37644 | E35: =DATEDIF(D35,'Chú giải'!$B$3,"Y") -> 23 | F35: Nhân viên văn phòng | G35: Công ty TNHH Tư vấn Bắc Hà | H35: 0900 000 034 | I35: nguyen.thanh.giang.034@example.com | J35: Số 2 ngõ 86 Núi Trúc, P. Kim Mã, Q. Ba Đình, Hà Nội | K35: Kim Mã | L35: Ba Đình | M35: V2 | N35: Không | O35: Không | P35: 6 | Q35: 3 | R35: 3.5 | T35: 46327 | U35: 6 | V35: 3 | W35: 2 | X35: 3 | Y35: 2 | Z35: 2 | AA35: 2 | AB35: 2 | AC35: 1 | AD35: 2 | AE35: 1 | AF35: 1 | AG35: 1 | AH35: 2 | AI35: 2 | AJ35: 2 | AK35: 2 | AL35: 1 | AN35: 0 | AQ35: 0 | AS35: 0 | AT35: Test đặc biệt | AU35: P21 | AV35: P21 · Bên A: Phạt A2=3 × A1=1
A36: RM035 | B36: Hoàng Gia Vinh | C36: Nam | D36: 37702 | E36: =DATEDIF(D36,'Chú giải'!$B$3,"Y") -> 23 | F36: Nhân viên bán hàng (ca kíp) | G36: Chuỗi điện máy Việt Tín | H36: 0900 000 035 | I36: hoang.gia.vinh.035@example.com | J36: Số 1 ngõ 118 Trung Kính, P. Yên Hòa, Q. Cầu Giấy, Hà Nội | K36: Yên Hòa | L36: Cầu Giấy | M36: V2 | N36: Có | O36: Không | P36: 6 | Q36: 3.5 | R36: 4 | S36: Hà Đông | T36: 46333 | U36: 3 | V36: 3 | W36: 1 | X36: 2 | Z36: 3 | AA36: 4 | AB36: 3 | AC36: 2 | AD36: 1 | AE36: 2 | AF36: 1 | AG36: 1 | AH36: 2 | AI36: 2 | AK36: 2 | AL36: 1 | AN36: 0 | AQ36: 0 | AS36: 0 | AT36: Ngẫu nhiên – thiếu dữ liệu | AV36: Bỏ trống: A3, E1
A37: RM036 | B37: Võ Quỳnh Vy | C37: Nữ | D37: 33638 | E37: =DATEDIF(D37,'Chú giải'!$B$3,"Y") -> 34 | F37: Giáo viên | G37: Trung tâm Anh ngữ Sunrise Hà Nội | H37: 0900 000 036 | I37: vo.quynh.vy.036@example.com | J37: Số 15 ngõ 132 Nguyễn Chí Thanh, P. Liễu Giai, Q. Ba Đình, Hà Nội | K37: Liễu Giai | L37: Ba Đình | M37: V3 | N37: Không | O37: Có | P37: 4 | Q37: 6 | R37: 6 | S37: Long Biên, Nam Từ Liêm | T37: 46333 | U37: 9 | V37: 6 | W37: 1 | X37: 1 | Y37: 2 | Z37: 3 | AA37: 3 | AB37: 1 | AC37: 2 | AD37: 2 | AE37: 1 | AF37: 1 | AG37: 1 | AH37: 2 | AI37: 2 | AJ37: 1 | AK37: 2 | AL37: 4 | AM37: 87 | AN37: 7 | AO37: 47 | AP37: 3.8 | AQ37: 0 | AS37: 0 | AT37: Ngẫu nhiên
A38: RM037 | B38: Phạm Quang Dương | C38: Nam | D38: 36931 | E38: =DATEDIF(D38,'Chú giải'!$B$3,"Y") -> 25 | F38: Nhân viên văn phòng | G38: Công ty CP Phần mềm Hà Thành | H38: 0900 000 037 | I38: pham.quang.duong.037@example.com | J38: Số 103 Giải Phóng, P. Phương Liệt, Q. Thanh Xuân, Hà Nội | K38: Phương Liệt | L38: Thanh Xuân | M38: V2 | N38: Không | O38: Không | P38: 6 | Q38: 3 | R38: 3.5 | T38: 46327 | U38: 6 | V38: 3 | W38: 2 | X38: 1 | Y38: 2 | Z38: 2 | AA38: 2 | AB38: 2 | AC38: 1 | AD38: 2 | AE38: 1 | AF38: 1 | AG38: 2 | AH38: 2 | AI38: 2 | AJ38: 2 | AK38: 2 | AL38: 1 | AN38: 0 | AQ38: 0 | AS38: 0 | AT38: Test đặc biệt | AU38: P17 | AV38: P17 · Bên B: Dị ứng nhẹ × thú nhỏ
A39: RM038 | B39: Nguyễn Phương Ngọc | C39: Nữ | D39: 36939 | E39: =DATEDIF(D39,'Chú giải'!$B$3,"Y") -> 25 | F39: Nhân viên văn phòng | G39: Công ty CP Phần mềm Hà Thành | H39: 0900 000 038 | I39: nguyen.phuong.ngoc.038@example.com | J39: Số 20 ngõ 98 Cầu Giấy, P. Dịch Vọng, Q. Cầu Giấy, Hà Nội | K39: Dịch Vọng | L39: Cầu Giấy | M39: V3 | N39: Không | O39: Không | P39: 6 | Q39: 3 | R39: 3.5 | T39: 46327 | U39: 6 | V39: 3 | W39: 2 | X39: 1 | Y39: 2 | Z39: 2 | AA39: 2 | AB39: 2 | AC39: 1 | AD39: 2 | AE39: 1 | AF39: 1 | AG39: 1 | AH39: 2 | AI39: 2 | AJ39: 2 | AK39: 2 | AL39: 1 | AN39: 0 | AQ39: 0 | AS39: 0 | AT39: Test đặc biệt | AU39: P03 | AV39: P03 · Bên B: Khác giới – chỉ một bên bật H1
A40: RM039 | B40: Bùi Kim Trâm | C40: Nữ | D40: 36588 | E40: =DATEDIF(D40,'Chú giải'!$B$3,"Y") -> 26 | F40: Kỹ sư xây dựng | G40: Công ty CP Xây dựng & Đầu tư Hồng Hà | H40: 0900 000 039 | I40: bui.kim.tram.039@example.com | J40: Số 86 Dương Nội, P. Dương Nội, Q. Hà Đông, Hà Nội | K40: Dương Nội | L40: Hà Đông | M40: V2 | N40: Có | O40: Không | P40: 6 | Q40: 6 | R40: 7.5 | T40: 46314 | U40: 6 | V40: 3 | W40: 2 | X40: 1 | Y40: 2 | Z40: 3 | AA40: 4 | AB40: 1 | AC40: 1 | AD40: 2 | AE40: 1 | AF40: 1 | AG40: 1 | AH40: 1 | AI40: 2 | AJ40: 3 | AK40: 3 | AL40: 4 | AM40: 87 | AN40: 2 | AO40: 79 | AP40: 3.6 | AQ40: 1 | AR40: 4.1 | AS40: 0 | AT40: Ngẫu nhiên
...

Sheet Cặp test đặc biệt
A1: Mã cặp | B1: Kịch bản | C1: Hồ sơ A (ID) | D1: Tên A | E1: Hồ sơ B (ID) | F1: Tên B | G1: Thiết lập khác biệt | H1: Kết quả kỳ vọng | I1: Mục tài liệu tham chiếu
A2: P01 | B2: Cặp lý tưởng, bonus vượt trần | C2: RM011 | D2: =INDEX('Hồ sơ'!$B$2:$B$101,MATCH(C2,'Hồ sơ'!$A$2:$A$101,0)) -> Đỗ Khánh Hương | E2: RM079 | F2: =INDEX('Hồ sơ'!$B$2:$B$101,MATCH(E2,'Hồ sơ'!$A$2:$A$101,0)) -> Đinh Hoài Lan | G2: 16 câu trả lời giống hệt nhau; cùng cơ quan, cùng phường, cùng V4, S1–S4 đều đạt ngưỡng bonus | H2: Qua Hard Gate. 16 sim = 1; B_emp đủ điều kiện vượt +0,15 nên bị cắt trần +0,15; P_pen = 0 → COMPAT ≥ 96, có thể chạm trần 99. | I2: V (pipeline), VIII (B_emp, trần +0,15), IX (trần 99)
A3: P02 | B3: Khác giới – cả hai tắt H1 | C3: RM043 | D3: =INDEX('Hồ sơ'!$B$2:$B$101,MATCH(C3,'Hồ sơ'!$A$2:$A$101,0)) -> Nguyễn Minh Bách | E3: RM060 | F3: =INDEX('Hồ sơ'!$B$2:$B$101,MATCH(E3,'Hồ sơ'!$A$2:$A$101,0)) -> Vũ Quỳnh Giang | G3: A nam, B nữ; H1 của cả hai = Không | H3: LOẠI – vi phạm H1 (cùng giới là mặc định). | I3: III – H1
A4: P03 | B4: Khác giới – chỉ một bên bật H1 | C4: RM068 | D4: =INDEX('Hồ sơ'!$B$2:$B$101,MATCH(C4,'Hồ sơ'!$A$2:$A$101,0)) -> Trần Tuấn Khoa | E4: RM038 | F4: =INDEX('Hồ sơ'!$B$2:$B$101,MATCH(E4,'Hồ sơ'!$A$2:$A$101,0)) -> Nguyễn Phương Ngọc | G4: A bật H1 (V3), B không bật H1 | H4: LOẠI – H1 yêu cầu CẢ HAI chủ động bật. | I4: III – H1
A5: P04 | B5: Khác giới – cả hai bật nhưng một bên V1 | C5: RM055 | D5: =INDEX('Hồ sơ'!$B$2:$B$101,MATCH(C5,'Hồ sơ'!$A$2:$A$101,0)) -> Lê Văn Minh | E5: RM076 | F5: =INDEX('Hồ sơ'!$B$2:$B$101,MATCH(E5,'Hồ sơ'!$A$2:$A$101,0)) -> Lê Thanh Ngọc | G5: Cả hai bật H1; A mới ở mức V1 | H5: LOẠI – A chưa đạt V2+. | I5: III – H1
A6: P05 | B6: Khác giới hợp lệ | C6: RM054 | D6: =INDEX('Hồ sơ'!$B$2:$B$101,MATCH(C6,'Hồ sơ'!$A$2:$A$101,0)) -> Nguyễn Văn Tài | E6: RM009 | F6: =INDEX('Hồ sơ'!$B$2:$B$101,MATCH(E6,'Hồ sơ'!$A$2:$A$101,0)) -> Nguyễn Hồng Yến | G6: Cả hai bật H1, đều ≥ V2 | H6: QUA H1; các ràng buộc khác đạt → được tính điểm bình thường. | I6: III – H1
A7: P06 | B7: Lệch tuổi vượt khung | C7: RM021 | D7: =INDEX('Hồ sơ'!$B$2:$B$101,MATCH(C7,'Hồ sơ'!$A$2:$A$101,0)) -> Nguyễn Công Dũng | E7: RM088 | F7: =INDEX('Hồ sơ'!$B$2:$B$101,MATCH(E7,'Hồ sơ'!$A$2:$A$101,0)) -> Đỗ Công Hoàng | G7: Chênh 8 tuổi, khung H2 = ±6 của cả hai | H7: LOẠI – vi phạm H2. | I7: III – H2
A8: P07 | B8: Lệch tuổi đúng biên | C8: RM050 | D8: =INDEX('Hồ sơ'!$B$2:$B$101,MATCH(C8,'Hồ sơ'!$A$2:$A$101,0)) -> Nguyễn Hồng Hà | E8: RM075 | F8: =INDEX('Hồ sơ'!$B$2:$B$101,MATCH(E8,'Hồ sơ'!$A$2:$A$101,0)) -> Nguyễn Minh Anh | G8: Chênh đúng 6 tuổi | H8: QUA H2 (biên ≤ 6). | I8: III – H2
A9: P08 | B9: Ngân sách vượt trần đối phương | C9: RM051 | D9: =INDEX('Hồ sơ'!$B$2:$B$101,MATCH(C9,'Hồ sơ'!$A$2:$A$101,0)) -> Phan Bảo Lan | E9: RM067 | F9: =INDEX('Hồ sơ'!$B$2:$B$101,MATCH(E9,'Hồ sơ'!$A$2:$A$101,0)) -> Hà Minh Hiền | G9: Ngân sách A 4,5 tr > trần B 3,5 tr | H9: LOẠI – vi phạm H3. | I9: III – H3
A10: P09 | B10: Khu vực không giao nhau | C10: RM049 | D10: =INDEX('Hồ sơ'!$B$2:$B$101,MATCH(C10,'Hồ sơ'!$A$2:$A$101,0)) -> Võ Đức Tiến | E10: RM040 | F10: =INDEX('Hồ sơ'!$B$2:$B$101,MATCH(E10,'Hồ sơ'!$A$2:$A$101,0)) -> Vũ Việt Dũng | G10: A chọn Cầu Giấy, B chọn Hà Đông | H10: LOẠI – vi phạm H4 (không có khu vực chung). | I10: III – H4
A11: P10 | B11: Ngày chuyển vào chênh 22 ngày | C11: RM089 | D11: =INDEX('Hồ sơ'!$B$2:$B$101,MATCH(C11,'Hồ sơ'!$A$2:$A$101,0)) -> Bùi Phương My | E11: RM030 | F11: =INDEX('Hồ sơ'!$B$2:$B$101,MATCH(E11,'Hồ sơ'!$A$2:$A$101,0)) -> Lương Ngọc Nhung | G11: 01/11/2026 so với 23/11/2026 | H11: LOẠI – vi phạm H5 (>21 ngày). | I11: III – H5
A12: P11 | B12: Ngày chuyển vào chênh đúng 21 ngày | C12: RM013 | D12: =INDEX('Hồ sơ'!$B$2:$B$101,MATCH(C12,'Hồ sơ'!$A$2:$A$101,0)) -> Đỗ Minh Bách | E12: RM008 | F12: =INDEX('Hồ sơ'!$B$2:$B$101,MATCH(E12,'Hồ sơ'!$A$2:$A$101,0)) -> Lê Thành Thịnh | G12: 01/11/2026 so với 22/11/2026 | H12: QUA H5 (biên ≤ 21 ngày). | I12: III – H5
A13: P12 | B13: Cam kết thấp hơn mức yêu cầu | C13: RM087 | D13: =INDEX('Hồ sơ'!$B$2:$B$101,MATCH(C13,'Hồ sơ'!$A$2:$A$101,0)) -> Nguyễn Quang Phong | E13: RM062 | F13: =INDEX('Hồ sơ'!$B$2:$B$101,MATCH(E13,'Hồ sơ'!$A$2:$A$101,0)) -> Trần Công Sơn | G13: A yêu cầu ≥ 6 tháng, B chỉ cam kết 3 tháng | H13: LOẠI – vi phạm H6. | I13: III – H6
... A29: P28 | B29: Không có bonus nào | C29: RM070 | D29: =INDEX('Hồ sơ'!$B$2:$B$101,MATCH(C29,'Hồ sơ'!$A$2:$A$101,0)) -> Trịnh Ngọc Giang | E29: RM093 | F29: =INDEX('Hồ sơ'!$B$2:$B$101,MATCH(E29,'Hồ sơ'!$A$2:$A$101,0)) -> Tạ Minh Thủy | G29: V1 cả hai, khác cơ quan, khác phường, ngân sách chênh 33%, chưa có S1–S4 | H29: QUA gate; B_emp = 0, P_pen = 0, RAW = S_base. | I29: VIII – B_emp

Sheet Chú giải
A1: ROOMORA – Bộ 100 hồ sơ mẫu cho Lifestyle Survey & Compatibility Score (v1.0)
A3: Ngày tham chiếu để tính tuổi | B3: 46299 | C3: Ô nhập liệu (chữ xanh): đổi ngày này thì cột Tuổi ở sheet Hồ sơ tự tính lại.
A5: Thống kê nhanh
A6: Tổng số hồ sơ | B6: =COUNTA('Hồ sơ'!A2:A101) -> 100
A7: Nam | B7: =COUNTIF('Hồ sơ'!C2:C101,"Nam") -> 50
A8: Nữ | B8: =COUNTIF('Hồ sơ'!C2:C101,"Nữ") -> 50
A9: Sinh viên | B9: =COUNTIF('Hồ sơ'!F2:F101,"Sinh viên*") -> 24
A10: Hồ sơ thuộc cặp test đặc biệt | B10: =COUNTIF('Hồ sơ'!AT2:AT101,"Test đặc biệt") -> 56
A11: Hồ sơ ngẫu nhiên thiếu dữ liệu | B11: =COUNTIF('Hồ sơ'!AT2:AT101,"Ngẫu nhiên – thiếu dữ liệu") -> 6
A12: Số cặp test đặc biệt | B12: =COUNTA('Cặp test đặc biệt'!A2:A29) -> 28
A14: Lưu ý khi dùng dữ liệu
A15: 1. | B15: Toàn bộ họ tên, SĐT, email, số nhà là dữ liệu giả lập. SĐT dạng 0900 000 xxx, email dùng miền example.com. Tên đường và phường là địa danh có thật ở Hà Nội.
A16: 2. | B16: Địa chỉ ghi theo dạng Phường – Quận (đúng với cách tài liệu v1.0 viết 'phường/quận'). Nếu app dùng đơn vị hành chính mới thì đổi lại khi import.
A17: 3. | B17: H4 để trống = chọn tất cả khu vực (đúng theo tài liệu).
A18: 4. | B18: Ô survey để trống = người dùng bỏ qua câu hỏi (sim = 0,50 và không hiển thị trong phần giải thích).
A19: 5. | B19: S1–S4 để trống = hồ sơ mới, chưa có hành vi đo được. Tài liệu chưa định nghĩa công thức sim cho S1–S4 và các mức V1–V4, nên mẫu chỉ cung cấp dữ liệu đầu vào.
A20: 6. | B20: Hàng nền vàng nhạt ở sheet Hồ sơ là hồ sơ thuộc 28 cặp test đặc biệt; mỗi cặp chỉ khác nhau ở thuộc tính cần kiểm tra, còn lại dùng giá trị trung tính (16 câu = phương án 'chuẩn' B1=2, A1=2...).
A21: 7. | B21: Chưa tính sẵn COMPAT cho từng cặp vì tài liệu chưa chỉ rõ tiêu chí nào thuộc tier T1/T2/T3 (k = 1,8 / 1,3 / 1,0) và công thức sim cho S1–S4. Sheet 'Cặp test đặc biệt' ghi kết quả kỳ vọng ở mức Hard Gate và P_pen / B_emp.
A23: Màu tiêu đề cột (sheet Hồ sơ)
A24: Thông tin cá nhân
A25: Ràng buộc ghép H1–H6
A26: Survey – tiêu chí CỨNG
A27: Survey – tiêu chí MỀM
A28: Chỉ số hệ thống S1–S4 & báo cáo
A29: Ghi chú mẫu
A31: Mã hoá đáp án survey
A32: Mã – Tiêu chí | B32: Loại | C32: Giá trị đáp án
A33: A1 – Giờ ngủ – giờ dậy | B33: CỨNG | C33: 1 Trước 22h30 | 2 22h30–23h30 | 3 23h30–01h00 | 4 Sau 01h00
A34: A2 – Làm ca đêm / giờ bất thường | B34: CỨNG | C34: 1 Không | 2 Thỉnh thoảng ≤2 buổi/tuần | 3 Thường xuyên ≥3 buổi/tuần
A35: A3 – Làm việc tại nhà | B35: CỨNG | C35: 1 Không | 2 1–2 ngày | 3 3–4 ngày | 4 Cả tuần
A36: B1 – Tiêu chuẩn vệ sinh | B36: CỨNG | C36: 1 Rất sạch | 2 Khá sạch | 3 Bình thường | 4 Hơi bừa
A37: B2 – Tần suất dọn không gian chung | B37: MỀM | C37: 1 Hằng ngày | 2 2–3 lần/tuần | 3 1 lần/tuần | 4 Khi thấy bẩn
A38: C1 – Mức riêng tư mong muốn | B38: CỨNG | C38: 1 Bất khả xâm phạm | 2 Thoải mái nhưng hỏi trước | 3 Rất mở, dùng chung được
A39: C2 – Giao tiếp & xử lý mâu thuẫn | B39: MỀM | C39: 1 Nói thẳng | 2 Nhắn tin riêng | 3 Nhịn cho qua | 4 Nhờ người thứ ba
A40: C3 – Mức độ thân thiết | B40: MỀM | C40: 1 Chỉ lịch sự | 2 Thân thiện vừa | 3 Thân thiết như bạn
A41: D1 – Thuốc lá / vape | B41: CỨNG | C41: 1 Không | 2 Chỉ ngoài ban công/khu riêng | 3 Hút trong phòng
A42: D2 – Dị ứng / sợ động vật | B42: CỨNG | C42: 1 Không | 2 Dị ứng nhẹ | 3 Dị ứng nặng/rất sợ
A43: D3 – Thú cưng | B43: CỨNG | C43: 1 Không nuôi | 2 Loại nhỏ | 3 Loại lớn
... A48: F2 – Cách chia chi phí chung | B48: MỀM | C48: 1 Chia đều | 2 Theo mức sử dụng | 3 Luân phiên | 4 Một người lo toàn bộ, người kia trả cố định
